Workbook

Sheet Assumptions
A1: CENTRAL ASSUMPTIONS — Fill This Sheet First
A2: All other sheets reference these cells. Update here and the whole model recalculates.
A4: SECTION A — COMPANY INFORMATION
A9: Company Name | B9: Nexura Logistics Group | C9: Used in all sheet headers
A10: Industry / Sector | B10: Transportation & Logistics | C10: Affects SASB materiality and EF selection
A11: Primary Country of Operations | B11: United States | C11: Used to select default grid emission factor
A12: Reporting Year (Current) | B12: 2024 | C12: Year of primary data being analyzed
A13: Reporting Year (Prior 1) | B13: 2023 | C13: For trend analysis — enter in Trend sheet
A14: SECTION B — FINANCIAL METRICS (for Intensity Calculations)
A15: Annual Revenue (USD Millions) | B15: 3850 | C15: USD Millions | D15: Used to calculate carbon intensity per $M revenue
A16: Number of Employees (FTE) | B16: 14200 | C16: Headcount | D16: Used to calculate carbon intensity per employee
A17: Total Production Volume (units) | B17: N/A | C17: Microsoft is a software, cloud, and services company; no consolidated production-volume metric is reported. | D17: For manufacturing companies — carbon per unit produced
A18: Floor Space / Facility Area | B18: N/A | C18: Microsoft does not publicly disclose total facility area in aggregate. | D18: For real estate, retail — carbon per m²
A19: Revenue Unit Note | B19: $3.85 Billion | C19: Text | D19: Important: ensure revenue is in $M not $B
A21: SECTION C — GLOBAL WARMING POTENTIAL (GWP) FACTORS — IPCC AR6 (2021)
A22: These factors convert non-CO₂ gases to CO₂ equivalents. AR6 values shown (default). Change only if your regulatory regime requires AR5 or AR4.
A23: Gas | B23: Chemical | C23: AR6 GWP (100-yr) | D23: AR5 GWP (100-yr) | E23: Your Selection | F23: Source
A24: Carbon Dioxide | B24: CO₂ | C24: 1 | D24: 1 | E24: 1 | F24: IPCC AR6, 2021
A25: Methane (fossil) | B25: CH₄ | C25: 29.8 | D25: 25 | E25: 29.8 | F25: IPCC AR6 WGI Table 7.SM.7
A26: Methane (biogenic) | B26: CH₄ | C26: 27.9 | D26: 25 | E26: 27.9 | F26: IPCC AR6 WGI Table 7.SM.7
A27: Nitrous Oxide | B27: N₂O | C27: 273 | D27: 298 | E27: 273 | F27: IPCC AR6 WGI Table 7.SM.7
A28: HFC-134a (refrigerant) | B28: CH₂FCF₃ | C28: 1526 | D28: 1430 | E28: 1526 | F28: IPCC AR6
A29: SF₆ (electrical equipment) | B29: SF₆ | C29: 25200 | D29: 22800 | E29: 25200 | F29: IPCC AR6
A32: Fiscal Year | B32: Revenue (USD) | C32: Employees
A33: 2024 | B33: 3850 | C33: 14200
A34: 2023 | B34: 3520 | C34: 13600
A35: 2022 | B35: 3210 | C35: 12800
A36: 2021 | B36: 2840 | C36: 11500
A37: 2020 | B37: 2450 | C37: 10200

Sheet Emission Factors
A1: EMISSION FACTORS REFERENCE LIBRARY — EPA, DEFRA, IEA 2023
A2: Reference only — do not edit. Factors are pre-loaded into calculation sheets. Update annually.
A4: TABLE 1 — STATIONARY COMBUSTION FACTORS (EPA Center for Corporate Climate Leadership 2023)
A5: # | B5: Fuel Type | C5: Unit | D5: CO₂ EF (kgCO₂/unit) | E5: CH₄ EF (gCH₄/unit) | F5: N₂O EF (gN₂O/unit) | G5: Source
A6: 1 | B6: Natural Gas | C6: MMBtu | D6: 53.06 | E6: 1 | F6: 0.1 | G6: EPA 2023 Table 1
A7: 2 | B7: Natural Gas | C7: m³ | D7: 1.879 | E7: 0.0354 | F7: 0.00354 | G7: EPA 2023 (converted)
A8: 3 | B8: Propane | C8: Gallon | D8: 5.68 | E8: 0.226 | F8: 0.023 | G8: EPA 2023 Table 1
A9: 4 | B9: Diesel Fuel / Fuel Oil No.2 | C9: Gallon | D9: 10.21 | E9: 0.41 | F9: 0.08 | G9: EPA 2023 Table 1
A10: 5 | B10: Diesel Fuel / Fuel Oil No.2 | C10: Litre | D10: 2.663 | E10: 0.139 | F10: 0.014 | G10: EPA 2023 (converted)
A11: 6 | B11: Residual Fuel Oil (No. 6) | C11: Gallon | D11: 11.27 | E11: 0.48 | F11: 0.1 | G11: EPA 2023 Table 1
A12: 7 | B12: Residual Fuel Oil (No. 6) | C12: Litre | D12: 3.122 | E12: 0.139 | F12: 0.014 | G12: EPA 2023 (converted)
A13: 8 | B13: LPG | C13: Gallon | D13: 5.68 | E13: 0.226 | F13: 0.023 | G13: EPA 2023 Table 1
A14: 9 | B14: LPG | C14: Litre | D14: 1.555 | E14: 0.0617 | F14: 0.0062 | G14: EPA 2023 (converted)
A15: 10 | B15: Coal — Bituminous | C15: Short Ton | D15: 2325 | E15: 274 | F15: 40 | G15: EPA 2023 Table 1
A16: 11 | B16: Coal — Sub-bituminous | C16: Short Ton | D16: 1676 | E16: 190 | F16: 28 | G16: EPA 2023 Table 1
A17: 12 | B17: Wood / Wood Waste | C17: Short Ton | D17: 1640 | E17: 300 | F17: 4 | G17: EPA 2023 Table 1
A18: 13 | B18: Municipal Solid Waste | C18: Short Ton | D18: 902 | E18: 318 | F18: 42 | G18: EPA 2023 Table 1
G19: epa.gov/system/files/documents/2023-03/ghg_emission_factors_hub.pdf
A21: TABLE 2 — MOBILE COMBUSTION FACTORS (EPA 2023 / DEFRA 2023)
A22: # | B22: Fuel Type | C22: Unit | D22: CO₂ EF (kgCO₂/unit) | E22: CH₄ EF (gCH₄/unit) | F22: N₂O EF (gN₂O/unit) | G22: Source
A23: 1 | B23: Gasoline — Passenger Cars | C23: Litre | D23: 2.312 | E23: 0.339 | F23: 0.033 | G23: DEFRA 2023 / (2.35) EPA 2023
A24: 2 | B24: Gasoline — Light-Duty Trucks | C24: Litre | D24: 2.312 | E24: 0.572 | F24: 0.057 | G24: DEFRA 2023 / EPA 2023
A25: 3 | B25: Diesel — Passenger Cars | C25: Litre | D25: 2.68 | E25: 0.046 | F25: 0.184 | G25: DEFRA 2023 / (2.69) EPA
A26: 4 | B26: Diesel — Heavy-Duty Trucks | C26: Litre | D26: 2.68 | E26: 0.06 | F26: 0.252 | G26: DEFRA 2023
A27: 5 | B27: Aviation Fuel (Jet A / Jet A-1) | C27: Litre | D27: 2.553 | E27: 0 | F27: 0 | G27: DEFRA 2023 / (2.53) EPA
A28: 6 | B28: Compressed Natural Gas (CNG) | C28: GJ | D28: 50.3 | E28: 0 | F28: 0 | G28: EPA 2023 / (50.3) EPA
A29: 7 | B29: Liquefied Natural Gas (LNG) | C29: Litre | D29: 2.75 | E29: 0 | F29: 0 | G29: DEFRA 2023
A31: TABLE 3 — ELECTRICITY GRID EMISSION FACTORS (IEA 2023 / EPA eGRID 2023)
A32: # | B32: Country / Region / Grid | C32: kgCO₂e / MWh (Location-Based) | D32: Source | E32: Year | F32: Notes
A33: 1 | B33: US National Average | C33: ~380-400 | D33: EPA eGRID 2023 | E33: 2023 | F33: Covers all NERC regions
A34: 2 | B34: US — CAMX (California) | C34: 194 | D34: EPA eGRID 2023 | E34: 2023 | F34: High renewables
A35: 3 | B35: US — ERCOT (Texas) | C35: 333 | D35: EPA eGRID 2023 | E35: 2023 | F35: Natural gas heavy
A36: 4 | B36: US — RFC (PJM Interconnection) | C36: 271 | D36: EPA eGRID 2023 | E36: 2023 | F36: Northeast / Midwest
A37: 5 | B37: US — WECC (Mountain) | C37: 319 | D37: EPA eGRID 2023 | E37: 2023 | F37: Mountain states
A38: 6 | B38: Canada National Average | C38: 110-140 | D38: Environment Canada 2022 | E38: 2022 | F38: High hydro share
A39: 7 | B39: European Union Average | C39: 230-260 | D39: European Environment Agency 2022 | E39: 2022 | F39: Weighted average
A40: 8 | B40: Germany | C40: 380-420 | D40: IEA 2022 | E40: 2022 | F40: Transitioning from coal
A41: 9 | B41: France | C41: 50-70 | D41: IEA 2022 | E41: 2022 | F41: Nuclear dominant
A42: 10 | B42: United Kingdom | C42: 207 | D42: DEFRA 2023 | E42: 2023 | F42: Official UK government factor
A43: 11 | B43: Sweden | C43: 10-20 | D43: IEA 2022 | E43: 2022 | F43: Hydro + nuclear dominant
...

Sheet Scope 1
A1: SCOPE 1 — DIRECT GHG EMISSIONS | GHG Protocol: All sources your organization directly controls
A2: Enter activity data (fuel consumed, distance driven, refrigerant leaked). Emission factors are pre-loaded from EPA/DEFRA tables.
A4: PART A — STATIONARY COMBUSTION (Boilers, Furnaces, Generators, Turbines)
A5: # | B5: Fuel Source | C5: Activity Quantity | D5: Activity Unit | E5: CO₂ EF (kgCO₂/unit) | F5: CH₄ EF (gCH₄/unit) | G5: N₂O EF (gN₂O/unit) | H5: CO₂ (tCO₂) | I5: CH₄ (tCO₂e) | J5: N₂O (tCO₂e) | K5: Total (tCO₂e)
A6: 1 | B6: Natural Gas | C6: 285000 | D6: MMBtu | E6: ='Emission Factors'!D6 -> 53.06 | F6: ='Emission Factors'!E6 -> 1 | G6: ='Emission Factors'!F6 -> 0.1 | H6: =C6*E6/1000 -> 15122.1 | I6: =C6*F6/1000000*Assumptions!E25*1000 -> 8493 | J6: =C6*G6/1000000*Assumptions!E27*1000 -> 7780.5 | K6: =H6+I6+J6 -> 31395.6
A7: 2 | B7: Natural Gas a | C7: 0 | D7: Cubic Metres (m³) | E7: ='Emission Factors'!D7 -> 1.879 | F7: ='Emission Factors'!E7 -> 0.0354 | G7: ='Emission Factors'!F7 -> 0.00354 | H7: =C7*E7/1000 -> 0 | I7: =C7*F7/1000000*Assumptions!E25*1000 -> 0 | J7: =C7*G7/1000000*Assumptions!E27*1000 -> 0 | K7: =H7+I7+J7 -> 0
A8: 3 | B8: Diesel Fuel / Fuel Oil No. 2 b | C8: 1850000 | D8: Litres | E8: ='Emission Factors'!D10 -> 2.663 | F8: ='Emission Factors'!E10 -> 0.139 | G8: ='Emission Factors'!F10 -> 0.014 | H8: =C8*E8/1000 -> 4926.55 | I8: =C8*F8/1000000*Assumptions!E25*1000 -> 7663.07 | J8: =C8*G8/1000000*Assumptions!E27*1000 -> 7070.7 | K8: =H8+I8+J8 -> 19660.32
A9: 4 | B9: Residual Fuel Oil (No. 6) c | C9: 0 | D9: Litres | E9: ='Emission Factors'!D11 -> 11.27 | F9: ='Emission Factors'!E11 -> 0.48 | G9: ='Emission Factors'!F11 -> 0.1 | H9: =C9*E9/1000 -> 0 | I9: =C9*F9/1000000*Assumptions!E25*1000 -> 0 | J9: =C9*G9/1000000*Assumptions!E27*1000 -> 0 | K9: =H9+I9+J9 -> 0
A10: 5 | B10: Liquefied Petroleum Gas (LPG) d | C10: 0 | D10: Litres | E10: ='Emission Factors'!D14 -> 1.555 | F10: ='Emission Factors'!E14 -> 0.0617 | G10: ='Emission Factors'!F14 -> 0.0062 | H10: =C10*E10/1000 -> 0 | I10: =C10*F10/1000000*Assumptions!E25*1000 -> 0 | J10: =C10*G10/1000000*Assumptions!E27*1000 -> 0 | K10: =H10+I10+J10 -> 0
A11: 6 | B11: Coal (Bituminous) e | C11: 0 | D11: Short Tons | E11: ='Emission Factors'!D15 -> 2325 | F11: ='Emission Factors'!E15 -> 274 | G11: ='Emission Factors'!F15 -> 40 | H11: =C11*E11/1000 -> 0 | I11: =C11*F11/1000000*Assumptions!E25*1000 -> 0 | J11: =C11*G11/1000000*Assumptions!E27*1000 -> 0 | K11: =H11+I11+J11 -> 0
A12: 7 | B12: Wood / Biomass f | C12: 0 | D12: Short Tons | E12: ='Emission Factors'!D16 -> 1676 | F12: ='Emission Factors'!E16 -> 190 | G12: ='Emission Factors'!F16 -> 28 | H12: =C12*E12/1000 -> 0 | I12: =C12*F12/1000000*Assumptions!E25*1000 -> 0 | J12: =C12*G12/1000000*Assumptions!E27*1000 -> 0 | K12: =H12+I12+J12 -> 0
A13: 8 | B13: Other Fuel (specify in notes) | C13: 0 | D13: Specify unit | E13: 0 | F13: 0 | G13: 0 | H13: =C13*E13/1000 -> 0 | I13: =C13*F13/1000000*Assumptions!E25*1000 -> 0 | J13: =C13*G13/1000000*Assumptions!E27*1000 -> 0 | K13: =H13+I13+J13 -> 0
B14: SUBTOTAL — Stationary Combustion | H14: =SUM(H6:H13) -> 20048.65 | I14: =SUM(I6:I13) -> 16156.07 | J14: =SUM(J6:J13) -> 14851.2 | K14: =SUM(K6:K13) -> 51055.92
A16: PART B — MOBILE COMBUSTION (Company Fleet, Owned/Leased Vehicles)
A17: # | B17: Fuel Source g | C17: Activity Quantity | D17: Activity Unit | E17: CO₂ EF (kgCO₂/unit) | F17: CH₄ EF (gCH₄/unit) | G17: N₂O EF (gN₂O/unit) | H17: CO₂ (tCO₂) | I17: CH₄ (tCO₂e) | J17: N₂O (tCO₂e) | K17: Total (tCO₂e)
A18: 1 | B18: Gasoline / Petrol (Passenger Cars) | C18: 1200000 | D18: Litres | E18: 2.35 | F18: 0.1 | G18: 0.02 | H18: =C18*E18/1000 -> 2820 | I18: =C18*F18/1000000*Assumptions!E25*1000 -> 3576 | J18: =C18*G18/1000000*Assumptions!E27*1000 -> 6552 | K18: =H18+I18+J18 -> 12948
A19: 2 | B19: Gasoline / Petrol (Heavy-Duty Trucks) | C19: 0 | D19: Litres | E19: 2.35 | F19: 0.1 | G19: 0.02 | H19: =C19*E19/1000 -> 0 | I19: =C19*F19/1000000*Assumptions!E25*1000 -> 0 | J19: =C19*G19/1000000*Assumptions!E27*1000 -> 0 | K19: =H19+I19+J19 -> 0
A20: 3 | B20: Diesel (Passenger Cars) | C20: 0 | D20: Litres | E20: 2.69 | F20: 0.11 | G20: 0.02 | H20: =C20*E20/1000 -> 0 | I20: =C20*F20/1000000*Assumptions!E25*1000 -> 0 | J20: =C20*G20/1000000*Assumptions!E27*1000 -> 0 | K20: =H20+I20+J20 -> 0
A21: 4 | B21: Diesel (Heavy-Duty Trucks) | C21: 285000000 | D21: Litres | E21: 2.69 | F21: 0.11 | G21: 0.02 | H21: =C21*E21/1000 -> 766650 | I21: =C21*F21/1000000*Assumptions!E25*1000 -> 934230 | J21: =C21*G21/1000000*Assumptions!E27*1000 -> 1556100 | K21: =H21+I21+J21 -> 3256980
A22: 5 | B22: Compressed Natural Gas (CNG) | C22: 0 | D22: GJ | E22: 56.1 | F22: 0.95 | G22: 0.1 | H22: =C22*E22/1000 -> 0 | I22: =C22*F22/1000000*Assumptions!E25*1000 -> 0 | J22: =C22*G22/1000000*Assumptions!E27*1000 -> 0 | K22: =H22+I22+J22 -> 0
A23: 6 | B23: Aviation Fuel (Jet-A) | C23: 1600000 | D23: Litres | E23: 2.54 | F23: 0.11 | G23: 0.02 | H23: =C23*E23/1000 -> 4064 | I23: =C23*F23/1000000*Assumptions!E25*1000 -> 5244.8 | J23: =C23*G23/1000000*Assumptions!E27*1000 -> 8736 | K23: =H23+I23+J23 -> 18044.8
A24: 7 | B24: Other / Specify | C24: 0 | D24: Specify unit | E24: 0 | F24: 0 | G24: 0 | H24: =C24*E24/1000 -> 0 | I24: =C24*F24/1000000*Assumptions!E25*1000 -> 0 | J24: =C24*G24/1000000*Assumptions!E27*1000 -> 0 | K24: =H24+I24+J24 -> 0
B25: SUBTOTAL — Mobile Combustion | H25: =SUM(H18:H24) -> 773534 | I25: =SUM(I18:I24) -> 943050.8 | J25: =SUM(J18:J24) -> 1571388 | K25: =SUM(K18:K24) -> 3287972.8
A27: PART C — FUGITIVE EMISSIONS (Refrigerants, Methane Leaks, SF₆)
A28: # | B28: Refrigerant / Gas Type | C28: Quantity Leaked | D28: Unit | E28: GWP Factor h | K28: Total (tCO₂e)
A29: 1 | B29: HFC-134a (Air Conditioning) | C29: 2800 | D29: kg | E29: 1430 | K29: =C29*E29/1000 -> 4004
A30: 2 | B30: HFC-410A (Air Conditioning) | C30: 1200 | D30: kg | E30: 2088 | K30: =C30*E30/1000 -> 2505.6
A31: 3 | B31: SF₆ (Electrical Switchgear) | C31: 0 | D31: kg | E31: 22800 | K31: =C31*E31/1000 -> 0
A32: 4 | B32: CH₄ — Natural Gas Leaks (pipeline) | C32: 0 | D32: kg | E32: 25 | K32: =C32*E32/1000 -> 0
A33: 5 | B33: CO₂ — Fire Suppression Systems | C33: 150 | D33: kg | E33: 1 | K33: =C33*E33/1000 -> 0.15
A34: 6 | B34: Other refrigerant (specify) | C34: 0 | D34: kg | E34: 0 | K34: =C34*E34/1000 -> 0
B35: SUBTOTAL — Fugitive Emissions | K35: =SUM(K29:K34) -> 6509.75
A37: ✦ SCOPE 1 TOTAL (tCO₂e) ✦ | K37: =K14+K25+K35 -> 3345538.5
B38: epa.gov/system/files/documents/2024-02/ghg-emission-factors-hub-2024.pdf | K38: Change cell for sum of all
B39: a EPA publishes factors per MMBtu, not per m³. These values are consistent with standard conversions from 1 m³ ≈ 0.0366 MMBtu.
B40: b CO₂: 73.96 kg/MMBtu ; CH₄: 3.0 g/MMBtu ; N₂O: 0.60 g/MMBtu --> Converted to liters (≈0.138 MMBtu/gal → 0.0365 MMBtu/L)
B41: c CO₂: 75.36 kg/MMBtu --> converted to liters
B42: d CO₂: 61.46 kg/MMBtu --> Converted to liters
B43: e CH₄: 11g/MMBtu x 24.93 MMBtu/short ton =274 g/short ton N₂O: 1.6 g/MMBtu x 24.93=40 g / short ton
B44: f EPA lists it as: CO₂: 1.64 metric tons CO₂ per short ton of wood → which is 1,640 kg CO₂/short ton
...

Sheet Scope 2
A1: SCOPE 2 — PURCHASED ENERGY | Dual Reporting: Market-Based AND Location-Based (GHG Protocol Required)
A2: GHG Protocol requires BOTH methods. Market-based reflects supplier contracts & RECs. Location-based uses grid averages.
A4: PART A — PURCHASED ELECTRICITY
A5: REFERENCE — Grid Emission Factors (kgCO₂e/MWh) | Source: IEA CO₂ Emissions from Fuel Combustion 2023 | CarbonFootprint.com (2025) Update annually
A6: Country/Region | B6: Grid EF (kgCO₂e/MWh)
A7: US Average | B7: 386 | C7: China | D7: 581
A8: US — California | B8: 230 | C8: India | D8: 713
A9: US — Texas (ERCOT) | B9: 430 | C9: Japan | D9: 471
A10: European Union Avg | B10: 231 | C10: Australia | D10: 680
A11: United Kingdom | B11: 207 | C11: Brazil | D11: 119
A12: Germany | B12: 380 | C12: Canada | D12: 130
A14: ELECTRICITY CONSUMPTION DATA
A15: # | B15: Facility / Region | C15: Electricity Consumed (MWh) | D15: Location-Based EF (kgCO₂/MWh) | E15: Market-Based EF (kgCO₂/MWh) | F15: RECs / PPAs (MWh covered) * | G15: Net Market- Based MWh | H15: Location-Based (tCO₂e) | I15: Market-Based (tCO₂e) | J15: Notes
A16: 1 | B16: Headquarters & Regional Offices (6 sites) | C16: 12500 | D16: 386 | E16: 8 | F16: 10000 | G16: =MAX(C16-F16,0) -> 2500 | H16: =C16*D16/1000 -> 4825 | I16: =G16*E16/1000 -> 20 | J16: [Notes on EF source, REC details]
A17: 2 | B17: Large Distribution Centers — East (12 DCs) | C17: 68000 | D17: 271 | E17: 8 | F17: 58000 | G17: =MAX(C17-F17,0) -> 10000 | H17: =C17*D17/1000 -> 18428 | I17: =G17*E17/1000 -> 80 | J17: [Notes on EF source, REC details]
A18: 3 | B18: Large Distribution Centers — Central/West (14 DCs) | C18: 72000 | D18: 386 | E18: 8 | F18: 62000 | G18: =MAX(C18-F18,0) -> 10000 | H18: =C18*D18/1000 -> 27792 | I18: =G18*E18/1000 -> 80 | J18: [Notes on EF source, REC details]
A19: 4 | B19: Truck Terminals & Cross-dock Facilities (10 sites) | C19: 25000 | D19: 386 | E19: 8 | F19: 18000 | G19: =MAX(C19-F19,0) -> 7000 | H19: =C19*D19/1000 -> 9650 | I19: =G19*E19/1000 -> 56 | J19: [Notes on EF source, REC details]
A20: 5 | B20: Last-Mile Sortation Centers (aggregate) | C20: 7500 | D20: 386 | E20: 8 | F20: 4000 | G20: =MAX(C20-F20,0) -> 3500 | H20: =C20*D20/1000 -> 2895 | I20: =G20*E20/1000 -> 28 | J20: [Notes on EF source, REC details]
A21: 6 | B21: IT Infrastructure & Network Operations | C21: 2800 | D21: 386 | E21: 8 | F21: 2500 | G21: =MAX(C21-F21,0) -> 300 | H21: =C21*D21/1000 -> 1080.8 | I21: =G21*E21/1000 -> 2.4 | J21: [Notes on EF source, REC details]
A22: 7 | B22: Other / Miscellaneous (workshops, fuel stations) | C22: 1800 | D22: 386 | E22: 8 | F22: 0 | G22: =MAX(C22-F22,0) -> 1800 | H22: =C22*D22/1000 -> 694.8 | I22: =G22*E22/1000 -> 14.4 | J22: [Notes on EF source, REC details]
B23: SUBTOTAL — Electricity | C23: =SUM(C16:C22) -> 189600 | F23: =SUM(F16:F22) -> 154500 | G23: =SUM(G16:G22) -> 35100 | H23: =SUM(H16:H22) -> 65365.6 | I23: =SUM(I16:I22) -> 280.8
A25: PART B — OTHER PURCHASED ENERGY (Steam, Heat, Cooling)
A26: # | B26: Energy Type | C26: Quantity Consumed | D26: Unit | E26: Emission Factor (kgCO₂e/unit) | H26: Location-Based (tCO₂e) | I26: Market-Based (tCO₂e) | J26: Notes
A27: 1 | B27: Purchased Steam | C27: 48000 | D27: GJ | E27: 66.4 | H27: =C27*E27/1000 -> 3187.2 | I27: =C27*E27/1000 -> 3187.2 | J27: [Source of emission factor]
A28: 2 | B28: Purchased Heat (District Heating) | C28: 0 | D28: GJ | E28: 66.4 | H28: =C28*E28/1000 -> 0 | I28: =C28*E28/1000 -> 0 | J28: [Source of emission factor]
A29: 3 | B29: Purchased Cooling (District Cooling) | C29: 0 | D29: GJ | E29: 66.4 | H29: =C29*E29/1000 -> 0 | I29: =C29*E29/1000 -> 0 | J29: [Source of emission factor]
B30: SUBTOTAL — Other Energy | H30: =SUM(H27:H29) -> 3187.2 | I30: =SUM(I27:I29) -> 3187.2
A32: ✦ SCOPE 2 TOTAL — LOCATION-BASED (tCO₂e) ✦ | H32: =H23+H30 -> 68552.8
A33: ✦ SCOPE 2 TOTAL — MARKET-BASED (tCO₂e) [USE THIS FOR REPORTING] ✦ | I33: =I23+I30 -> 3468
A34: *(Renewable Energy Certificates) ; PPAs (Power Purchase Agreements) ; GOs (Guarantees of Origin, in Europe) ; I‑RECs (International RECs, global markets)

Sheet Scope 3
A1: SCOPE 3 — VALUE CHAIN EMISSIONS | Cover at least 3 of the 15 categories most material to your industry
A2: Scope 3 typically represents 70–90% of total footprint. Use spend-based method where activity data is unavailable.
A4: SCOPE 3 CATEGORY OVERVIEW — Mark which categories are material for your company (✓ = Include, N/A = Not applicable)
B5: Cat # | C5: Category Name | D5: Stream | E5: Typical Method | F5: Material for your industry? | G5: Estimated % of S3 (Reasonable Industry averages) | H5: Notes: It is NOT an official GHG Protocol requirement
B6: 1 | C6: Purchased Goods & Services | D6: Upstream | E6: Spend-based or supplier-specific | F6: High for manufacturing/retail | G6: ~40% | H6: Often true, for manufacturing, retail, food, apparel, pharma — this is usually the largest Scope 3 category.
B7: 2 | C7: Capital Goods | D7: Upstream | E7: Spend-based | F7: High for capital-intensive industries | G7: ~5% | H7: Reasonable. Higher for construction, tech hardware, automotive; lower for services.
B8: 3 | C8: Fuel & Energy-Related Activities | D8: Upstream | E8: Activity-based | F8: ALL companies | G8: ~3% | H8: Typical.
B9: 4 | C9: Upstream Transportation & Distribution | D9: Upstream | E9: Spend/distance-based | F9: Retail, manufacturing | G9: ~5% | H9: Reasonable. Retail, manufacturing, e‑commerce often fall in this range.
B10: 5 | C10: Waste Generated in Operations | D10: Upstream | E10: Activity-based | F10: Manufacturing, food & beverage | G10: ~1% | H10: Typical. Only large for food, agriculture, chemicals.
B11: 6 | C11: Business Travel | D11: Upstream | E11: Activity-based (km × EF) | F11: Services, consulting, financial | G11: ~1% | H11: Typical. Higher for consulting, finance, tech
B12: 7 | C12: Employee Commuting | D12: Upstream | E12: Survey-based | F12: Office-heavy companies | G12: ~1% | H12: Typical. Office-heavy companies
B13: 8 | C13: Upstream Leased Assets | D13: Upstream | E13: Asset-specific | F13: Companies with leased fleet/space | G13: ~2% | H13: Depends. Only relevant if you lease equipment or space.
B14: 9 | C14: Downstream Transportation | D14: Downstream | E14: Spend/distance-based | F14: Consumer goods, e-commerce | G14: ~5% | H14: Typical. Big for consumer goods and e‑commerce.
B15: 10 | C15: Processing of Sold Products | D15: Downstream | E15: Industry-specific | F15: Chemicals, materials suppliers | G15: ~3% | H15: Industry-specific. Chemicals, materials, components.
B16: 11 | C16: Use of Sold Products | D16: Downstream | E16: Activity-based (product use) | F16: High for electronics, vehicles, appliances | G16: ~25% | H16: Very common. Electronics, appliances, vehicles — often the largest category.
... B20: 15 | C20: Investments | D20: Downstream | E20: PCAF / portfolio-based | F20: Financial institutions, banks | G20: ~30% | H20: True for finance. Banks, PE, VC — this is usually the dominant category.
A23: CATEGORY 1 — PURCHASED GOODS & SERVICES (Spend-Based Method)
A24: # | B24: Supplier / Spend Category | C24: Annual Spend (USD) | D24: EEIO Factor (kgCO₂e per $)a | E24: Typical USEEIP Range b | F24: EEIO Source | G24: Spend in $000s | H24: Notes | J24: tCO₂e | K24: Data Confidence | L24: Notes
A25: 1 | B25: Raw Materials / Commodities | C25: 180000000 | D25: 0.35 | E25: 0.2 - 1.20 | F25: US EPA USEEIO v2.0 | H25: Plastics material & resin manufacturing; Steel mills; Paper mills | J25: =C25*D25/1000 -> 63000 | K25: Medium | L25: [Enter data source / assumption]
A26: 2 | B26: Manufactured Components / Parts | C26: 95000000 | D26: 0.52 | E26: 0.4 - 1.50 | F26: US EPA USEEIO v2.0 | H26: Semiconductor manufacturing; Electronic component manufacturing; Fabricated metal products | J26: =C26*D26/1000 -> 49400 | K26: Medium | L26: [Enter data source / assumption]
A27: 3 | B27: Packaging Materials | C27: 42000000 | D27: 0.63 | E27: 0.5 -1.00 | F27: US EPA USEEIO v2.0 | H27: Paperboard container manufacturing; Plastics packaging manufacturing | J27: =C27*D27/1000 -> 26460 | K27: Medium | L27: [Enter data source / assumption]
A28: 4 | B28: Information Technology / Hardware | C28: 78000000 | D28: 0.85 | E28: 0.7 - 1.40 | F28: US EPA USEEIO v2.0 | H28: Computer manufacturing; Electronic equipment manufacturing | J28: =C28*D28/1000 -> 66300 | K28: Medium | L28: [Enter data source / assumption]
A29: 5 | B29: Professional / Business Services | C29: 55000000 | D29: 0.12 | E29: 0.05 - 0.20 | F29: US EPA USEEIO v2.0 | H29: Management consulting services; Legal services; Accounting services | J29: =C29*D29/1000 -> 6600 | K29: Medium | L29: [Enter data source / assumption]
A30: 6 | B30: Food & Beverage (for operations) | C30: 8500000 | D30: 0.95 | E30: 0.8 -1.60 | F30: US EPA USEEIO v2.0 | H30: Food manufacturing; Beverage manufacturing | J30: =C30*D30/1000 -> 8075 | K30: Medium | L30: [Enter data source / assumption]
A31: 7 | B31: Construction / Building Materials | C31: 120000000 | D31: 0.42 | E31: 0.3 - 0 70 | F31: US EPA USEEIO v2.0 | H31: Cement manufacturing; Ready‑mix concrete; Construction services | J31: =C31*D31/1000 -> 50400 | K31: Medium | L31: [Enter data source / assumption]
A32: 8 | B32: Other goods/services (specify) | C32: 65000000 | D32: 0.25 | E32: varies | J32: =C32*D32/1000 -> 16250 | K32: Medium | L32: [Enter data source / assumption]
B33: SUBTOTAL — Category 1 | C33: =SUM(C25:C32) -> 643500000 | J33: =SUM(J25:J32) -> 286485
B34: a EEIO = Environmentally Extended Input–Output. How many kg of CO₂e are emitted per dollar spent on a product or service.
B35: b Typical range of emission intensities (kgCO₂e per dollar spent) found across sectors in the USEEIO model — the U.S. Environmentally Extended Input–Output model published by the EPA.
A36: CATEGORY 3 — FUEL & ENERGY RELATED ACTIVITIES (Upstream Emissions from Purchased Energy)
A37: # | B37: Activity | C37: Scope 2 Electricity (MWh) | D37: T&D Loss Factor c (% of consumption) | E37: Well-to-Tank EF d (kgCO₂e/MWh) DEFRA | F37: Step 1 — Calculate T&D loss electricity | G37: Step 2 — Multiply by the DEFRA upstream electricity factor | H37: Step 3 — Convert to tonnes | I37: Emission Factor (EPA e grid) for subregion e.g. Chicago | J37: tCO₂e | K37: (tCO₂e for Category 3) tCO2e | L37: Confidence | M37: Notes
A38: 1 | B38: T&D Losses — Purchased Electricity | C38: ='Scope 2'!H32+0 -> 68552.8 | D38: 0.042 | E38: 26.5 | F38: =C38*D38 -> 2879.2176 | G38: =F38*E38 -> 76299.266 | H38: =G38/1000 -> 76.299266 | I38: 416 | J38: =C38*D38*E38/1000 -> 76.299266 | K38: =I38*F38/1000 -> 1197.7545 | M38: [Enter source]
A39: 2 | B39: Well-to-Tank — Natural Gas (for Scope 1) | C39: 300675 | D39: 0.042 | E39: 15.4 | F39: =C39*D39 -> 12628.35 | G39: =F39*E39 -> 194476.59 | H39: =G39/1000 -> 194.47659 | J39: =C39*E39/1000 -> 4630.395 | M39: [Enter source]
A40: 3 | B40: Well-to-Tank — Diesel Fuel (for Scope 1) | C40: 10231500 | D40: 0.042 | E40: 16.7 | F40: =C40*D40 -> 429723 | G40: =F40*E40 -> 7176374.1 | H40: =G40/1000 -> 7176.3741 | J40: =C40*E40/1000 -> 170866.05 | M40: [Enter source]
A41: 4 | B41: Well-to-Tank — Gasoline (for Scope 1) | C41: 37920 | D41: 0.042 | E41: 14.8 | F41: =C41*D41 -> 1592.64 | G41: =F41*E41 -> 23571.072 | H41: =G41/1000 -> 23.571072 | J41: =C41*E41/1000 -> 561.216 | M41: [Enter source]
B42: SUBTOTAL — Category 3 | I42: * it was provided | J42: =SUM(J38:J41) -> 176133.96
B43: UK DEFRA/BEIS. EPA does not publish Well‑to‑Tank (WTT) emission factors for electricity or fuels.
B44: c T&D = Transmission & Distribution.
B45: d Upstream emissions from producing, processing, and delivering the fuel before it is used.
A46: CATEGORY 6 — BUSINESS TRAVEL (Activity-Based: Distance × Emission Factor)
...

Sheet Summary & Intensity
A1: CARBON FOOTPRINT SUMMARY & INTENSITY RATIOS
A2: All values pull automatically from Scope 1, 2, and 3 sheets. Review after completing data entry.
A4: SECTION 1 — SCOPE TOTALS (tCO₂e)
A5: Scope | B5: Description | C5: tCO₂e | D5: % of Total (S1+S2+S3) | E5: % of Total (S1+S2 only) | F5: Compared to Prior Year | G5: Target | H5: Notes
A6: Scope 1 | B6: Direct Emissions (combustion, fleet, fugitive) | C6: ='Scope 1'!K37 -> 3345538.5 | D6: =IFERROR(C6/C11,0) -> 0.75333226 | E6: =IFERROR((C6-F6)/ABS(F6),0) -> 22.079046 | F6: =144960 -> 144960 | G6: 430000 | H6: [Source / methodology note]
A7: Scope 2 (Market-Based) | B7: Purchased Energy — Market-Based [PRIMARY] | C7: ='Scope 2'!I33 -> 3468 | D7: =IFERROR(C7/C11,0) -> 0.00078090756 | E7: =IFERROR((C7-F7)/ABS(F7),0) -> -0.99117858 | F7: =393134 -> 393134 | G7: 15000 | H7: [Source / methodology note]
A8: Scope 2 (Location-Based) | B8: Purchased Energy — Location-Based [SECONDARY] | C8: ='Scope 2'!H32 -> 68552.8 | D8: [Supplemental — not in totals] | E8: =IFERROR((C8-F8)/ABS(F8),0) -> -0.99151301 | F8: =8077403 -> 8077403 | G8: [Enter reduction target tCO₂e] | H8: [Source / methodology note]
A9: Scope 3 | B9: Value Chain Emissions (all categories) | C9: ='Scope 3'!J70 -> 1091980.1 | D9: =IFERROR(C9/C11,0) -> 0.24588683 | E9: =IFERROR((C9-F9)/ABS(F9),0) -> -0.93340366 | F9: 16397000 | G9: 1100000 | H9: [Source / methodology note]
A11: TOTAL — Scope 1 + Scope 2 (MB) + Scope 3 | C11: =C6+C7+C9 -> 4440986.6 | F11: =F6+F7+F9 -> 16935094
A12: TOTAL — Scope 1 + Scope 2 (MB) only | C12: =C6+C7 -> 3349006.5 | F12: =F6+F7 -> 538094
A14: SECTION 2 — CARBON INTENSITY RATIOS (how much carbon it emits relative to a meaningful business metric. It is a mandatory component of
A15: Intensity Metric | B15: Formula | C15: Current Year (tCO₂e / unit) | D15: Prior Year (tCO₂e / unit) | E15: Change (%) | F15: Industry Benchmark | G15: vs. Benchmark | H15: Unit
A16: Carbon Intensity — Revenue | B16: tCO₂e per $M revenue | C16: =IFERROR(C11/Assumptions!B15,0) -> 1153.503 | D16: =F11/211915 -> 79.91456 | E16: =IFERROR((C16-D16)/ABS(D16),0) -> 13.434203 | F16: [Industry benchmark] | G16: =IFERROR((C16-F16)/ABS(F16),0) -> 0 | H16: tCO₂e / $M revenue
A17: Carbon Intensity — Employee | B17: tCO₂e per FTE employee | C17: =IFERROR(C11/Assumptions!B16,0) -> 312.74554 | D17: =F11/221000 -> 76.629385 | E17: =IFERROR((C17-D17)/ABS(D17),0) -> 3.0812743 | F17: [Industry benchmark] | G17: =IFERROR((C17-F17)/ABS(F17),0) -> 0 | H17: tCO₂e / employee
A18: Carbon Intensity — Production | B18: tCO₂e per unit of output (N/A) | C18: =IFERROR(C11/Assumptions!B17,0) -> 0 | D18: 0 | E18: =IFERROR((C18-D18)/ABS(D18),0) -> 0 | F18: [Industry benchmark] | G18: =IFERROR((C18-F18)/ABS(F18),0) -> 0 | H18: tCO₂e / unit
A19: Scope 1 Intensity — Revenue | B19: Scope 1 tCO₂e per $M revenue | C19: =IFERROR('Scope 1'!K37/Assumptions!B15,0) -> 868.97103 | D19: ='Trend Analysis'!C7/211915 -> 0.67385508 | E19: =IFERROR((C19-D19)/ABS(D19),0) -> 1288.5518 | F19: [Industry benchmark] | G19: =IFERROR((C19-F19)/ABS(F19),0) -> 0 | H19: tCO₂e / $M revenue
A20: Scope 2 MB Intensity — Revenue | B20: Scope 2 tCO₂e per $M revenue | C20: =IFERROR('Scope 2'!I33/Assumptions!B15,0) -> 0.90077922 | D20: ='Reduction Trajectory'!F19/211915 -> 0.18120473 | E20: =IFERROR((C20-D20)/ABS(D20),0) -> 3.971058 | F20: [Industry benchmark] | G20: =IFERROR((C20-F20)/ABS(F20),0) -> 0 | H20: tCO₂e / $M revenue
A21: Scope 3 Intensity — Revenue | B21: Scope 3 tCO₂e per $M revenue | C21: =IFERROR('Scope 3'!J70/Assumptions!B15,0) -> 283.6312 | D21: ='Reduction Trajectory'!F21/211915 -> 9.1546139 | E21: =IFERROR((C21-D21)/ABS(D21),0) -> 29.982323 | F21: [Industry benchmark] | G21: =IFERROR((C21-F21)/ABS(F21),0) -> 0 | H21: tCO₂e / $M revenue
A22: % Renewable Energy | B22: RECs as % of total electricity | C22: ='Scope 2'!F23/'Scope 2'!C23 -> 0.81487342 | D22: =23567502/24007868 -> 0.98165743 | E22: =IFERROR((C22-D22)/ABS(D22),0) -> -0.16990042 | F22: [Industry benchmark] | G22: =IFERROR((C22-F22)/ABS(F22),0) -> 0 | H22: %
A24: SECTION 3 — SCOPE BREAKDOWN (% of Total S1+S2+S3)
A25: Scope | B25: tCO₂e | C25: % Share | D25: GHG Protocol Guidance | E25: Best Practice Target
A26: Scope 1 | B26: ='Scope 1'!K37 -> 3345538.5 | C26: =IFERROR(B26/B29,0) -> 0.75333226 | D26: Reduce through fuel switching & efficiency
A27: Scope 2 (Market-Based) | B27: ='Scope 2'!I33 -> 3468 | C27: =IFERROR(B27/B29,0) -> 0.00078090756 | D27: Reduce through RECs, PPAs, on-site renewables
A28: Scope 3 | B28: ='Scope 3'!J70 -> 1091980.1 | C28: =IFERROR(B28/B29,0) -> 0.24588683 | D28: Reduce through supply chain engagement & product design
A29: TOTAL | B29: =B26+B27+B28 -> 4440986.6 | C29: 100%

Sheet Trend Analysis
A1: EMISSIONS TREND ANALYSIS — 3-Year Historical Data & Chart
A2: Enter prior years manually. Current year pulls from Scope sheets automatically. Chart updates automatically.
A4: ABSOLUTE EMISSIONS TREND (tCO₂e) — Enter prior years | Current year auto-calculates
A5: Metric | B5: Year -2 (oldest) | C5: Year -1 | D5: Current Year (auto) | E5: YoY Change (yr-2 to yr-1) | F5: YoY Change (yr-1 to curr) | G5: 3-Year Cumulative Change | H5: Notes / Targets
A6: Reporting Year | B6: 2022 | C6: 2023 | D6: 2024
A7: Scope 1 Total (tCO₂e) | B7: ='Reduction Trajectory'!E17 -> 118200 | C7: ='Reduction Trajectory'!F17 -> 142800 | D7: ='Scope 1'!K37 -> 3345538.5 | E7: =IFERROR((C7-B7)/ABS(B7),0) -> 0.20812183 | F7: =IFERROR((D7-C7)/ABS(C7),0) -> 22.428141 | G7: =IFERROR((D7-B7)/ABS(B7),0) -> 27.304048 | H7: [Target or benchmark]
A8: Scope 2 Location-Based (tCO₂e) | B8: ='Reduction Trajectory'!E18 -> 98600 | C8: ='Reduction Trajectory'!F18 -> 102400 | D8: ='Scope 2'!H32 -> 68552.8 | E8: =IFERROR((C8-B8)/ABS(B8),0) -> 0.038539554 | F8: =IFERROR((D8-C8)/ABS(C8),0) -> -0.33053906 | G8: =IFERROR((D8-B8)/ABS(B8),0) -> -0.30473834 | H8: [Target or benchmark]
A9: Scope 2 Market-Based (tCO₂e) | B9: ='Reduction Trajectory'!E19 -> 62800 | C9: ='Reduction Trajectory'!F19 -> 38400 | D9: ='Scope 2'!I33 -> 3468 | E9: =IFERROR((C9-B9)/ABS(B9),0) -> -0.38853503 | F9: =IFERROR((D9-C9)/ABS(C9),0) -> -0.9096875 | G9: =IFERROR((D9-B9)/ABS(B9),0) -> -0.94477707 | H9: [Target or benchmark]
A10: Scope 3 Total (tCO₂e) | B10: ='Reduction Trajectory'!E21 -> 1780000 | C10: ='Reduction Trajectory'!F21 -> 1940000 | D10: ='Scope 3'!J70 -> 1091980.1 | E10: =IFERROR((C10-B10)/ABS(B10),0) -> 0.08988764 | F10: =IFERROR((D10-C10)/ABS(C10),0) -> -0.43712364 | G10: =IFERROR((D10-B10)/ABS(B10),0) -> -0.38652802 | H10: [Target or benchmark]
A11: TOTAL (S1+S2MB+S3) (tCO₂e) | B11: ='Reduction Trajectory'!E22 -> 1961000 | C11: ='Reduction Trajectory'!F22 -> 2121600 | D11: ='Scope 1'!K37+'Scope 2'!I33+'Scope 3'!J70 -> 4440986.6 | E11: =IFERROR((C11-B11)/ABS(B11),0) -> 0.081896991 | F11: =IFERROR((D11-C11)/ABS(C11),0) -> 1.0932252 | G11: =IFERROR((D11-B11)/ABS(B11),0) -> 1.2646541 | H11: [Target or benchmark]
A12: Carbon Intensity — Revenue (tCO₂e/$M) | B12: =B11/Assumptions!B35 -> 610.90343 | C12: =C11/Assumptions!B34 -> 602.72727 | D12: =IFERROR(('Scope 1'!K37+'Scope 2'!I33+'Scope 3'!J70)/Assumptions!B15,0) -> 1153.503 | E12: =IFERROR((C12-B12)/ABS(B12),0) -> -0.01338371 | F12: =IFERROR((D12-C12)/ABS(C12),0) -> 0.9138059 | G12: =IFERROR((D12-B12)/ABS(B12),0) -> 0.88819208 | H12: [Target or benchmark]
A13: Carbon Intensity — Employee (tCO₂e/FTE) | B13: =B11/Assumptions!C35 -> 153.20312 | C13: =C11/Assumptions!C34 -> 156 | D13: =IFERROR(('Scope 1'!K37+'Scope 2'!I33+'Scope 3'!J70)/Assumptions!B16,0) -> 312.74554 | E13: =IFERROR((C13-B13)/ABS(B13),0) -> 0.018255992 | F13: =IFERROR((D13-C13)/ABS(C13),0) -> 1.0047791 | G13: =IFERROR((D13-B13)/ABS(B13),0) -> 1.0413783 | H13: [Target or benchmark]
A14: Renewable Energy % of Electricity | B14: 0.52 | C14: 0.66 | D14: =IFERROR(SUM('Scope 2'!F16:F22)/SUM('Scope 2'!C16:C22),0) -> 0.81487342 | E14: =IFERROR((C14-B14)/ABS(B14),0) -> 0.26923077 | F14: =IFERROR((D14-C14)/ABS(C14),0) -> 0.23465669 | G14: =IFERROR((D14-B14)/ABS(B14),0) -> 0.56706426 | H14: [Target or benchmark]
A16: REDUCTION TARGETS — Enter company-stated targets for chart overlay
A17: Target | B17: Target Year | C17: Baseline Year | D17: Baseline Value (tCO₂e) | E17: % Reduction Required | F17: Target Value (tCO₂e) | G17: Annual reductions | H17: Target Type | I17: Source
A18: Net Zero Commitment | B18: 2040 | C18: 2024 | D18: ='Reduction Trajectory'!C22 -> 1403800 | E18: 0.5 | F18: =D18*(1-E18) -> 701900 | G18: =(D18-F18)/(B18-C18) -> 43868.75 | H18: Science-Based Target (SBTi) | I18: Nexura Sustainability Report 2024
A19: Near-Term Scope 1+2 Target | B19: 2030 | C19: 2024 | D19: 600000 | E19: 0.42 | F19: =D19*(1-E19) -> 348000 | G19: =(D19-F19)/(B19-C19) -> 42000 | H19: SBTi 1.5°C aligned | I19: SBTi Commitment Letter 2023
A20: Scope 3 Fleet Electrification Target | B20: 2035 | C20: 2024 | D20: 1640000 | E20: 0.35 | F20: =D20*(1-E20) -> 1066000 | G20: =(D20-F20)/(B20-C20) -> 52181.818 | H20: SBTi value chain | I20: Nexura Sustainability Report 2024

Sheet Reduction Trajectory
B2: Emission Trajectory Chart
B3: Enter your data in the yellow input cells below · The chart updates automatically · GHG Protocol Framework
B5: 📥 INPUT TABLE — Type your values in the YELLOW cells (tCO₂e or MtCO₂e — be consistent)
B6: 🟡 Yellow = enter your data | E6: 🔵 Blue = auto-calculated formula | H6: Growth assumed | I6: CAGR | J6: Report based info previous year
B7: Category / Year → | C7: 2024 | D7: 2025 | E7: 2026 | F7: 2027 | G7: 2028 | H7: 2029 | I7: 2030
B8: Business as usual | C8: =C9 -> 1403800 | D8: =H22 -> 16456070 | E8: =I22 -> 17422778 | F8: =J22 -> 18446275 | G8: =K22 -> 19529898 | H8: =L22 -> 20677178 | I8: =M22 -> 21891855
B9: ='Trend Analysis'!A18 -> Net Zero Commitment | C9: ='Trend Analysis'!D18 -> 1403800 | D9: =C9-'Trend Analysis'!G18 -> 1359931.2 | E9: =D9-'Trend Analysis'!G18 -> 1316062.5 | F9: =E9-'Trend Analysis'!G18 -> 1272193.8 | G9: =F9-'Trend Analysis'!G18 -> 1228325 | H9: =G9-'Trend Analysis'!G18 -> 1184456.2 | I9: =H9-'Trend Analysis'!G18 -> 1140587.5
B10: ='Trend Analysis'!A19 -> Near-Term Scope 1+2 Target | C10: ='Trend Analysis'!D19 -> 600000 | D10: =C10-'Trend Analysis'!G19 -> 558000 | E10: =D10-'Trend Analysis'!G19 -> 516000 | F10: =E10-'Trend Analysis'!G19 -> 474000 | G10: =F10-'Trend Analysis'!G19 -> 432000 | H10: =G10-'Trend Analysis'!G19 -> 390000 | I10: =H10-'Trend Analysis'!G19 -> 348000
B11: ='Trend Analysis'!A20 -> Scope 3 Fleet Electrification Target | C11: ='Trend Analysis'!D20 -> 1640000 | D11: =C11-'Trend Analysis'!G20 -> 1587818.2 | E11: =D11-'Trend Analysis'!G20 -> 1535636.4 | F11: =E11-'Trend Analysis'!G20 -> 1483454.5 | G11: =F11-'Trend Analysis'!G20 -> 1431272.7 | H11: =G11-'Trend Analysis'!G20 -> 1379090.9 | I11: =H11-'Trend Analysis'!G20 -> 1326909.1
B15: 📊 SCOPE BREAKDOWN INPUT — Decompose your Residual Emissions by Scope (mtCO2e) Prediction with CAGR: =(FY2024/FY2020)^(1/4)-1 → then each year = previous_year × (1+CAGR)
B16: Scope / Year → | C16: 2020 | D16: 2021 | E16: 2022 | F16: 2023 | G16: 2024 | H16: 2025 | I16: 2026 | J16: 2027 | K16: 2028 | L16: 2029 | M16: 2030
B17: 🌿 Scope 1 — Direct Emissions | C17: 78400 | D17: 95600 | E17: 118200 | F17: 142800 | G17: 143510 | H17: =(1+((G17/C17)^(1/4)-1))*G17 -> 166925.89 | I17: 158197 | J17: 166095 | K17: 174387 | L17: 183093 | M17: 192234
B18: ⚡ Scope 2 — Purchased Energy (location based) | C18: 85200 | D18: 92400 | E18: 98600 | F18: 102400 | G18: 9955368 | H18: =('Trend Analysis'!F8+1)*G18 -> 6664730 | I18: =('Trend Analysis'!F8+1)*H18 -> 4461776.4 | J18: =('Trend Analysis'!F8+1)*I18 -> 2986985 | K18: =('Trend Analysis'!F8+1)*J18 -> 1999669.8 | L18: =('Trend Analysis'!F8+1)*K18 -> 1338700.8 | M18: =('Trend Analysis'!F8+1)*L18 -> 896207.9
B19: ⚡ Scope 2 — Purchased Energy (market based) | C19: 85200 | D19: 80100 | E19: 62800 | F19: 38400 | G19: 259090 | H19: 224928 | I19: 195271 | J19: 169524 | K19: 147172 | L19: 127767 | M19: 110921
B20: Subtotal (Scope 1 + 2 Market-based) | C20: 574219 | D20: 553109 | E20: 427442 | F20: 538094 | G20: 402600 | H20: 368403 | I20: 337110 | J20: 308476 | K20: 282274 | L20: 258297 | M20: 236357
B21: 🔗 Scope 3 — Value Chain | C21: 1240000 | D21: 1520000 | E21: 1780000 | F21: 1940000 | G21: 15140000 | H21: 16114753 | I21: 17152263 | J21: 18256571 | K21: 19431977 | L21: 20683059 | M21: 22014689
B22: 📊 TOTAL (S1+S2+S3) | C22: 1403800 | D22: 1688100 | E22: 1961000 | F22: 2121600 | G22: 15543000 | H22: 16456070 | I22: 17422778 | J22: 18446275 | K22: 19529898 | L22: 20677178 | M22: 21891855
B24: 🏁 MILESTONES — Label key points on your pathway (shown as annotations on chart)
B25: Year | C25: Label / Commitment | D25: Target Value (tCO₂e) | E25: Notes
B26: 2030 | C26: Net-Zero Commitment | D26: ='Trend Analysis'!F18 -> 701900 | E26: ='Trend Analysis'!H18 -> Science-Based Target (SBTi)
B27: 2030 | C27: Near-Term SBTi (Scope 1+2) | D27: ='Trend Analysis'!F19 -> 348000 | E27: ='Trend Analysis'!H19 -> SBTi 1.5°C aligned
B28: 2030 | C28: Scope 3 Reduction Target | D28: ='Trend Analysis'!F20 -> 1066000 | E28: ='Trend Analysis'!H20 -> SBTi value chain
C29: [Enter milestone year] | E29: [Enter note]
C30: [Enter milestone year] | E30: [Enter note]
B33: 📈 NET ZERO PATHWAY CHART — Auto-generated from your inputs above
B58: Note: Trajectory slope can change depend on company pace, new technologies and strategic actions
B59: 📊 SCOPE 1 / 2 / 3 BREAKDOWN CHART — build

Sheet Documentation
A1: METHODOLOGY DOCUMENTATION (ASSUMPTIONS LOG)
A2: Document EVERY emission factor, boundary decision, and methodology choice here. This becomes your report's Methodology section.
A4: EMISSION FACTOR LOG — Document every factor used in your calculations
A5: # | B5: Scope / Category | C5: Fuel/Energy Type | D5: EF Value Used | E5: EF Unit | F5: EF Source | G5: Year of EF | H5: Rationale / Notes
A6: 1 | B6: Scope 1 — Stationary | C6: Natural Gas | D6: 53.06 kgCO₂/MMBtu | E6: kgCO₂/MMBtu | F6: EPA CCCL 2023 | G6: 2023 | H6: Used EPA Table 1 national average. Update if company uses a regional specific factor.
A7: 2 | B7: Scope 1 — Stationary | C7: Diesel Fuel | D7: 2.698 kgCO₂/litre | E7: kgCO₂/litre | F7: EPA CCCL 2023 | G7: 2023 | H7: Converted from gallon-based factor. Verify unit consistency with fuel bills.
A8: 3 | B8: Scope 1 — Mobile | C8: Gasoline (fleet) | D8: 2.312 kgCO₂/litre | E8: kgCO₂/litre | F8: DEFRA 2023 | G8: 2023 | H8: DEFRA UK government conversion factors — appropriate for global use.
A9: 4 | B9: Scope 1 — Fugitive | C9: HFC-134a | D9: 1526 kgCO₂e/kg | E9: kgCO₂e/kg | F9: IPCC AR6 2021 | G9: 2021 | H9: GWP from IPCC AR6. Quantity from maintenance records or refrigerant purchase data.
A10: 5 | B10: Scope 2 — Electricity | C10: Grid EF — [specify region] | D10: [Enter value] kgCO₂e/MWh | E10: kgCO₂e/MWh | F10: [Enter source — IEA/EPA/DEFRA] | G10: [Enter year] | H10: [Enter rationale for choosing this regional factor]
A11: 6 | B11: Scope 2 — Market-Based | C11: Supplier/Residual EF | D11: [Enter value] kgCO₂e/MWh | E11: kgCO₂e/MWh | F11: [Enter source] | G11: [Enter year] | H11: [Explain if company holds RECs, PPAs, or uses utility supplier factor]
A12: 7 | B12: Scope 3 — Cat 1 | C12: EEIO Factor — [spend category] | D12: [Enter value] kgCO₂e/$ | E12: kgCO₂e/USD | F12: US EPA USEEIO v2.0 | G12: 2022 | H12: Spend-based method used due to lack of primary supplier data. Uncertainty range ±30-50%.
A13: 8 | B13: Scope 3 — Cat 3 | C13: T&D Loss Factor — Electricity | D13: 5% loss factor | E13: % | F13: IEA / Local utility | G13: [Enter year] | H13: Applied to total purchased electricity to estimate upstream T&D emissions.
A14: 9 | B14: Scope 3 — Cat 6 | C14: Business Travel — Air EF | D14: 0.255 kgCO₂e/km (short haul) | E14: kgCO₂e/km | F14: DEFRA 2023 | G14: 2023 | H14: Economy class assumed unless company travel data specifies class breakdown.
A15: 10 | B15: [Enter] | C15: [Enter] | D15: [Enter] | E15: [Enter] | F15: [Enter] | G15: [Enter] | H15: [Enter]
A16: 11 | B16: [Enter] | C16: [Enter] | D16: [Enter] | E16: [Enter] | F16: [Enter] | G16: [Enter] | H16: [Enter]
A17: 12 | B17: [Enter] | C17: [Enter] | D17: [Enter] | E17: [Enter] | F17: [Enter] | G17: [Enter] | H17: [Enter]
... A22: 17 | B22: [Enter] | C22: [Enter] | D22: [Enter] | E22: [Enter] | F22: [Enter] | G22: [Enter] | H22: [Enter]
A25: BOUNDARY & METHODOLOGY DECISIONS
A26: Decision Area | B26: Your Choice
A27: Organizational boundary method | B27: Operational Control — includes all owned and long-term leased (>1yr) facilities and vehicles
A28: Geographic boundary | B28: United States (primary), Canada and Mexico (cross-border operations, minor share)
A29: Scope 2 accounting method primary | B29: Market-Based primary; Location-Based reported as supplemental per GHG Protocol
A30: GWP version used | B30: IPCC AR6 (2021)
A31: Scope 3 categories selected | B31: Categories 1, 2, 3, 4, 5, 6, 7, 9, 12, 13 — excludes Cat 10, 11, 14, 15 (not applicable)
A32: Estimation method for gaps | B32: Spend-based (USEEIO v2.0) for Cat 1; Activity-based for Cat 3, 6; Headcount-based for Cat 7
A33: Base year | B33: 2024 (first year of full GHG inventory)

Sheet EF hubs
B2: Emission Factors for Greenhouse Gas Inventories
F3: Last Modified: January 15, 2025
C4: Blue text indicates an update from the 2024 version of this document.
C5: Typically, greenhouse gas emissions are reported in units of carbon dioxide equivalent (CO2e). Gases are converted to CO2e by multiplying by their global warming potential (GWP). In most cases, the emission factors listed in this document generally have not been converted to CO2e. To do so, multiply the emissions by the corresponding GWP listed in the table below.
C7: Gas | D7: 100-Year GWP
C8: CH4 | D8: 28
C9: N2O | D9: 265
C10: Source: Intergovernmental Panel on Climate Change (IPCC), Fifth Assessment Report (AR5), 2013. See the source note to Table 11 for further explanation.
B12: Table 1 | C12: Stationary Combustion
C14: Fuel Type | D14: Heat Content (HHV) | E14: CO2 Factor | F14: CH4 Factor | G14: N2O Factor | H14: CO2 Factor | I14: CH4 Factor | J14: N2O Factor
D15: mmBtu per short ton | E15: kg CO2 per mmBtu | F15: g CH4 per mmBtu | G15: g N2O per mmBtu | H15: kg CO2 per short ton | I15: g CH4 per short ton | J15: g N2O per short ton
C16: Coal and Coke
C17: Anthracite | D17: 25.09 | E17: 103.69 | F17: 11 | G17: 1.6 | H17: 2602 | I17: 276 | J17: 40
C18: Bituminous | D18: 24.93 | E18: 93.28 | F18: 11 | G18: 1.6 | H18: 2325 | I18: 274 | J18: 40
C19: Sub-bituminous | D19: 17.25 | E19: 97.17 | F19: 11 | G19: 1.6 | H19: 1676 | I19: 190 | J19: 28
C20: Lignite | D20: 14.21 | E20: 97.72 | F20: 11 | G20: 1.6 | H20: 1389 | I20: 156 | J20: 23
C21: Mixed (Commercial Sector) | D21: 21.39 | E21: 94.27 | F21: 11 | G21: 1.6 | H21: 2016 | I21: 235 | J21: 34
C22: Mixed (Electric Power Sector) | D22: 19.73 | E22: 95.52 | F22: 11 | G22: 1.6 | H22: 1885 | I22: 217 | J22: 32
C23: Mixed (Industrial Coking) | D23: 26.28 | E23: 93.9 | F23: 11 | G23: 1.6 | H23: 2468 | I23: 289 | J23: 42
C24: Mixed (Industrial Sector) | D24: 22.35 | E24: 94.67 | F24: 11 | G24: 1.6 | H24: 2116 | I24: 246 | J24: 36
C25: Coal Coke | D25: 24.8 | E25: 113.67 | F25: 11 | G25: 1.6 | H25: 2819 | I25: 273 | J25: 40
C26: Other Fuels - Solid
C27: Municipal Solid Waste | D27: 9.95 | E27: 90.7 | F27: 32 | G27: 4.2 | H27: 902 | I27: 318 | J27: 42
C28: Petroleum Coke (Solid) | D28: 30 | E28: 102.41 | F28: 32 | G28: 4.2 | H28: 3072 | I28: 960 | J28: 126
C29: Plastics | D29: 38 | E29: 75 | F29: 32 | G29: 4.2 | H29: 2850 | I29: 1216 | J29: 160
C30: Tires | D30: 28 | E30: 85.97 | F30: 32 | G30: 4.2 | H30: 2407 | I30: 896 | J30: 118
C31: Biomass Fuels - Solid
C32: Agricultural Byproducts | D32: 8.25 | E32: 118.17 | F32: 32 | G32: 4.2 | H32: 975 | I32: 264 | J32: 35
C33: Peat | D33: 8 | E33: 111.84 | F33: 32 | G33: 4.2 | H33: 895 | I33: 256 | J33: 34
C34: Solid Byproducts | D34: 10.39 | E34: 105.51 | F34: 32 | G34: 4.2 | H34: 1096 | I34: 332 | J34: 44
C35: Wood and Wood Residuals | D35: 17.48 | E35: 93.8 | F35: 7.2 | G35: 3.6 | H35: 1640 | I35: 126 | J35: 63
D36: mmBtu per scf | E36: kg CO2 per mmBtu | F36: g CH4 per mmBtu | G36: g N2O per mmBtu | H36: kg CO2 per scf | I36: g CH4 per scf | J36: g N2O per scf
C37: Natural Gas
C38: Natural Gas | D38: 0.001026 | E38: 53.06 | F38: 1 | G38: 0.1 | H38: 0.05444 | I38: 0.00103 | J38: 0.0001
C39: Other Fuels - Gaseous
C40: Blast Furnace Gas | D40: 9.2e-05 | E40: 274.32 | F40: 0.022 | G40: 0.1 | H40: 0.02524 | I40: 2e-06 | J40: 9e-06
C41: Coke Oven Gas | D41: 0.000599 | E41: 46.85 | F41: 0.48 | G41: 0.1 | H41: 0.02806 | I41: 0.000288 | J41: 6e-05
C42: Fuel Gas | D42: 0.001388 | E42: 59 | F42: 3 | G42: 0.6 | H42: 0.08189 | I42: 0.004164 | J42: 0.000833
C43: Propane Gas | D43: 0.002516 | E43: 61.46 | F43: 3 | G43: 0.6 | H43: 0.15463 | I43: 0.007548 | J43: 0.00151
C44: Biomass Fuels - Gaseous
...

Sheet 📊 Dashboard
B2: 🌍 CARBON FOOTPRINT EXECUTIVE DASHBOARD
B3: GHG Protocol Framework · All figures link live to Scope 1, 2, 3 & Assumptions sheets
B6: SCOPE 1 DIRECT | D6: SCOPE 2 MARKET-BASED | F6: SCOPE 3 VALUE CHAIN | H6: TOTAL S1 + S2 + S3
B7: ='Scope 1'!K37 -> 3345538.5 | D7: ='Scope 2'!I33 -> 3468 | F7: ='Scope 3'!J70 -> 1091980.1 | H7: ='Summary & Intensity'!C11 -> 4440986.6
B8: tCO₂e | D8: tCO₂e | F8: tCO₂e | H8: tCO₂e
B9: Combustion · Fleet · Fugitive | D9: Purchased electricity (primary) | F9: Upstream & downstream emissions | H9: Combined GHG inventory
B11: 📊 SCOPE BREAKDOWN — Linked live from Summary & Intensity sheet
B12: Scope | C12: Description | D12: tCO₂e | E12: % of Total | F12: Location-Based | G12: Mkt-Based | H12: Target | I12: Status
B13: Scope 1 | C13: Direct Emissions | D13: ='Summary & Intensity'!C6 -> 3345538.5 | E13: =IFERROR(D13/'Summary & Intensity'!C11,0) -> 0.75333226 | F13: — | G13: ='Scope 2'!H32 -> 68552.8 | H13: — | I13: 🟡 Input needed
B14: Scope 2 | C14: Purchased Energy | D14: ='Summary & Intensity'!C7 -> 3468 | E14: =IFERROR(D14/'Summary & Intensity'!C11,0) -> 0.00078090756 | F14: ='Scope 2'!H32 -> 68552.8 | G14: ='Scope 2'!I33 -> 3468 | H14: — | I14: 🟡 Input needed
B15: Scope 3 | C15: Value Chain Emissions | D15: ='Summary & Intensity'!C9 -> 1091980.1 | E15: =IFERROR(D15/'Summary & Intensity'!C11,0) -> 0.24588683 | F15: — | G15: — | H15: — | I15: 🟡 Input needed
B16: TOTAL (S1+S2+S3) | C16: Combined Inventory | D16: ='Summary & Intensity'!C11 -> 4440986.6 | E16: =IFERROR(D16/'Summary & Intensity'!C11,0) -> 1 | F16: — | G16: — | H16: — | I16: ✅ Calculated
B18: 🎯 REDUCTION TARGETS — Linked live from Trend Analysis sheet
B19: Target | C19: Target Year | D19: Baseline Year | E19: Baseline (tCO₂e) | F19: % Required | G19: Target (tCO₂e) | H19: Annual Reduction | I19: Type
B20: ='Trend Analysis'!A18 -> Net Zero Commitment | C20: ='Trend Analysis'!B18 -> 2040 | D20: ='Trend Analysis'!C18 -> 2024 | E20: ='Trend Analysis'!D18 -> 1403800 | F20: ='Trend Analysis'!E18 -> 0.5 | G20: ='Trend Analysis'!F18 -> 701900 | H20: ='Trend Analysis'!G18 -> 43868.75 | I20: ='Trend Analysis'!H18 -> Science-Based Target (SBTi)
B21: ='Trend Analysis'!A19 -> Near-Term Scope 1+2 Target | C21: ='Trend Analysis'!B19 -> 2030 | D21: ='Trend Analysis'!C19 -> 2024 | E21: ='Trend Analysis'!D19 -> 600000 | F21: ='Trend Analysis'!E19 -> 0.42 | G21: ='Trend Analysis'!F19 -> 348000 | H21: ='Trend Analysis'!G19 -> 42000 | I21: ='Trend Analysis'!H19 -> SBTi 1.5°C aligned
B22: ='Trend Analysis'!A20 -> Scope 3 Fleet Electrification Target | C22: ='Trend Analysis'!B20 -> 2035 | D22: ='Trend Analysis'!C20 -> 2024 | E22: ='Trend Analysis'!D20 -> 1640000 | F22: ='Trend Analysis'!E20 -> 0.35 | G22: ='Trend Analysis'!F20 -> 1066000 | H22: ='Trend Analysis'!G20 -> 52181.818 | I22: ='Trend Analysis'!H20 -> SBTi value chain
B24: 📐 CARBON INTENSITY RATIOS — Linked live from Summary & Intensity sheet
B25: Metric | C25: Formula | D25: Current Year | E25: Prior Year | F25: Change (%) | G25: Industry Benchmark | H25: vs Benchmark | I25: Unit
B26: Carbon Intensity — Revenue | C26: tCO₂e / $M revenue | D26: ='Summary & Intensity'!C15 -> Current Year (tCO₂e / unit) | E26: ='Summary & Intensity'!D15 -> Prior Year (tCO₂e / unit) | F26: ='Summary & Intensity'!E15 -> Change (%) | G26: ='Summary & Intensity'!F15 -> Industry Benchmark | H26: ='Summary & Intensity'!G15 -> vs. Benchmark | I26: tCO₂e/$M
B27: Carbon Intensity — Employee | C27: tCO₂e / FTE | D27: ='Summary & Intensity'!C16 -> 1153.503 | E27: ='Summary & Intensity'!D16 -> 79.91456 | F27: ='Summary & Intensity'!E16 -> 13.434203 | G27: ='Summary & Intensity'!F16 -> [Industry benchmark] | H27: ='Summary & Intensity'!G16 -> 0 | I27: tCO₂e/FTE
B28: % Renewable Energy | C28: RECs / Total elec. | D28: ='Summary & Intensity'!C22 -> 0.81487342 | E28: ='Summary & Intensity'!D22 -> 0.98165743 | F28: ='Summary & Intensity'!E22 -> -0.16990042 | G28: ='Summary & Intensity'!F22 -> [Industry benchmark] | H28: ='Summary & Intensity'!G22 -> 0 | I28: %
B29: Scope 1 Intensity | C29: S1 / $M revenue | D29: ='Summary & Intensity'!C19 -> 868.97103 | E29: ='Summary & Intensity'!D19 -> 0.67385508 | F29: ='Summary & Intensity'!E19 -> 1288.5518 | G29: ='Summary & Intensity'!F19 -> [Industry benchmark] | H29: ='Summary & Intensity'!G19 -> 0 | I29: tCO₂e/$M
B30: Scope 2 MB Intensity | C30: S2MB / $M revenue | D30: ='Summary & Intensity'!C20 -> 0.90077922 | E30: ='Summary & Intensity'!D20 -> 0.18120473 | F30: ='Summary & Intensity'!E20 -> 3.971058 | G30: ='Summary & Intensity'!F20 -> [Industry benchmark] | H30: ='Summary & Intensity'!G20 -> 0 | I30: tCO₂e/$M
B31: Scope 3 Intensity | C31: S3 / $M revenue | D31: ='Summary & Intensity'!C21 -> 283.6312 | E31: ='Summary & Intensity'!D21 -> 9.1546139 | F31: ='Summary & Intensity'!E21 -> 29.982323 | G31: ='Summary & Intensity'!F21 -> [Industry benchmark] | H31: ='Summary & Intensity'!G21 -> 0 | I31: tCO₂e/$M
B33: ⚙️ COMPANY INFORMATION — Linked live from Assumptions sheet
B34: Field | C34: Value | D34: Notes | E34: Status
B35: Company Name | C35: =Assumptions!B9 -> Nexura Logistics Group | D35: =Assumptions!C9 -> Used in all sheet headers | E35: —
B36: Industry / Sector | C36: =Assumptions!B10 -> Transportation & Logistics | D36: =Assumptions!C10 -> Affects SASB materiality and EF selection | E36: —
B37: Country of Operations | C37: =Assumptions!B11 -> United States | D37: =Assumptions!C11 -> Used to select default grid emission factor | E37: —
B38: Reporting Year | C38: =Assumptions!B12 -> 2024 | D38: =Assumptions!C12 -> Year of primary data being analyzed | E38: —
B39: Annual Revenue ($M) | C39: =Assumptions!B15 -> 3850 | D39: =Assumptions!C15 -> USD Millions | E39: Required for intensity ratios
B40: Employees (FTE) | C40: =Assumptions!B16 -> 14200 | D40: =Assumptions!C16 -> Headcount | E40: Required for intensity ratios
B42: All KPIs update automatically when activity data is entered in Scope 1, 2, 3 and Assumptions sheets · GHG Protocol Corporate Standard
